Workbook

Sheet 說明
A1: Lab 3 MOSFET 實驗 數據記錄簿
A2: 電子學實作系列第 9 週（11/7 六）．App_Lab3.pdf．當天用筆電直接填
A4: 助教公告的當天範圍
B5: 實驗一 I_D-V_DS：至少量一條導通的（V_GS = 2／4／6 V 擇一以上），填表並畫 I_D-V_DS 關係圖
B6: 實驗二 I_D-V_GS：至少量一條導通的（V_DS = 3／5 V 擇一以上），填表並畫 I_D-V_GS 關係圖
B7: 實驗三（導通電阻）、實驗四（LED 開關）、第二部分（共源級放大器）行有餘力再完成
A9: 怎麼用這個檔
B10: 黃底 = 當天要填的格子，其他欄位是公式或 LTspice 預報值，不用動
B11: 實驗一填「R1 壓降 V_R1」，I_D 欄會自動算成 V_R1 / 1 kΩ
B12: 實驗二填「汲極對地電壓 V_D」，I_D 欄會自動算成 (V_DS − V_D) / 100 Ω
B13: 兩張散佈圖會跟著填的格子自動長出來，收工前看一眼形狀對不對
B14: 「交報告用」分頁已照講義版面排好，數字由前兩張表帶過來，直接複製貼進報告
A16: 量測注意
B17: 實驗一的 R1 串在「源極」：電源讀數 V_GS、V_DS 都含 R1 壓降，不等於元件端點電壓
B18: 實驗二的 R1 串在「汲極」、源極接地：電源讀數 V_GS 就是元件真正的 V_GS
B19: 2N7000 規格書的 V_GS(th) 範圍是 0.8～3.0 V，量到 1.5 V 或 2.8 V 都算正常
B20: LTspice 預報用的是 BS170（同族替身），導通門檻與手上那顆不會完全一樣，只拿來對形狀

Sheet 實驗一 特性曲線
A1: 實驗一 輸出特性曲線 I_D-V_DS（講義第 6–7 頁）
A2: R1 = 1 kΩ 串在源極．填 R1 壓降，I_D 自動換算．V_GS = 0 V 那組全是 0 是正常的（截止區）
B4: V_GS = 0 V | E4: V_GS = 2 V | H4: V_GS = 4 V | K4: V_GS = 6 V
A5: V_DS 設定 (V) | B5: V_R1 量測 (V) | C5: I_D (mA) | D5: LTspice (mA) | E5: V_R1 量測 (V) | F5: I_D (mA) | G5: LTspice (mA) | H5: V_R1 量測 (V) | I5: I_D (mA) | J5: LTspice (mA) | K5: V_R1 量測 (V) | L5: I_D (mA) | M5: LTspice (mA)
A6: 1 | C6: =IF(B6="","",B6/1000.0*1000) | D6: 0 | F6: =IF(E6="","",E6/1000.0*1000) | G6: 0.0153 | I6: =IF(H6="","",H6/1000.0*1000) | J6: 0.9858 | L6: =IF(K6="","",K6/1000.0*1000) | M6: 0.9957
A7: 2 | C7: =IF(B7="","",B7/1000.0*1000) | D7: 0 | F7: =IF(E7="","",E7/1000.0*1000) | G7: 0.0158 | I7: =IF(H7="","",H7/1000.0*1000) | J7: 1.6567 | L7: =IF(K7="","",K7/1000.0*1000) | M7: 1.9867
A8: 3 | C8: =IF(B8="","",B8/1000.0*1000) | D8: 0 | F8: =IF(E8="","",E8/1000.0*1000) | G8: 0.0162 | I8: =IF(H8="","",H8/1000.0*1000) | J8: 1.6621 | L8: =IF(K8="","",K8/1000.0*1000) | M8: 2.958
A9: 4 | C9: =IF(B9="","",B9/1000.0*1000) | D9: 0 | F9: =IF(E9="","",E9/1000.0*1000) | G9: 0.0165 | I9: =IF(H9="","",H9/1000.0*1000) | J9: 1.6654 | L9: =IF(K9="","",K9/1000.0*1000) | M9: 3.5621
A10: 5 | C10: =IF(B10="","",B10/1000.0*1000) | D10: 0 | F10: =IF(E10="","",E10/1000.0*1000) | G10: 0.0168 | I10: =IF(H10="","",H10/1000.0*1000) | J10: 1.668 | L10: =IF(K10="","",K10/1000.0*1000) | M10: 3.5701
A12: 助教只要求至少一條導通的（V_GS = 2／4／6 V 擇一以上）；V_GS = 0 V 那組建議還是量一次，當作「截止區電流為零」的證據。
A13: V_GS = 6 V 在低 V_DS 時每加 1 V 電流約多 1 mA，那是 1 kΩ 的斜率、不是元件的三極管電阻。

Sheet 實驗二 轉移曲線
A1: 實驗二 轉移特性曲線 I_D-V_GS 與臨界電壓（講義第 8–9 頁）
A2: R1 = 100 Ω 串在汲極、源極接地．填汲極對地電壓 V_D，I_D 自動換算成 (V_DS − V_D)/100 Ω
B4: V_DS = 1 V | E4: V_DS = 3 V | H4: V_DS = 5 V
A5: V_GS 設定 (V) | B5: V_D 量測 (V) | C5: I_D (mA) | D5: LTspice (mA) | E5: V_D 量測 (V) | F5: I_D (mA) | G5: LTspice (mA) | H5: V_D 量測 (V) | I5: I_D (mA) | J5: LTspice (mA)
A6: 0.5 | C6: =IF(B6="","",(1.0-B6)/100.0*1000) | D6: 0 | F6: =IF(E6="","",(3.0-E6)/100.0*1000) | G6: 0 | I6: =IF(H6="","",(5.0-H6)/100.0*1000) | J6: 0
A7: 1 | C7: =IF(B7="","",(1.0-B7)/100.0*1000) | D7: 0 | F7: =IF(E7="","",(3.0-E7)/100.0*1000) | G7: 0 | I7: =IF(H7="","",(5.0-H7)/100.0*1000) | J7: 0
A8: 2 | C8: =IF(B8="","",(1.0-B8)/100.0*1000) | D8: 0.0185 | F8: =IF(E8="","",(3.0-E8)/100.0*1000) | G8: 0.0197 | I8: =IF(H8="","",(5.0-H8)/100.0*1000) | J8: 0.0207
A9: 3 | C9: =IF(B9="","",(1.0-B9)/100.0*1000) | D9: 8.6331 | F9: =IF(E9="","",(3.0-E9)/100.0*1000) | G9: 24.7749 | I9: =IF(H9="","",(5.0-H9)/100.0*1000) | J9: 31.346
A10: 4 | C10: =IF(B10="","",(1.0-B10)/100.0*1000) | D10: 9.3596 | F10: =IF(E10="","",(3.0-E10)/100.0*1000) | G10: 28.0076 | I10: =IF(H10="","",(5.0-H10)/100.0*1000) | J10: 46.5403
A11: 5 | C11: =IF(B11="","",(1.0-B11)/100.0*1000) | D11: 9.5782 | F11: =IF(E11="","",(3.0-E11)/100.0*1000) | G11: 28.7152 | I11: =IF(H11="","",(5.0-H11)/100.0*1000) | J11: 47.8244
A13: 加密掃描（找 V_th 用） | C13: 選用的 V_DS (V) →
A14: V_GS 設定 (V) | B14: V_D 量測 (V) | C14: I_D (mA) | D14: √I_D
C15: =IF(OR(A15="",B15="",$D$13=""),"",($D$13-B15)/100.0*1000) | D15: =IF(C15="","",SQRT(C15))
C16: =IF(OR(A16="",B16="",$D$13=""),"",($D$13-B16)/100.0*1000) | D16: =IF(C16="","",SQRT(C16))
C17: =IF(OR(A17="",B17="",$D$13=""),"",($D$13-B17)/100.0*1000) | D17: =IF(C17="","",SQRT(C17))
C18: =IF(OR(A18="",B18="",$D$13=""),"",($D$13-B18)/100.0*1000) | D18: =IF(C18="","",SQRT(C18))
C19: =IF(OR(A19="",B19="",$D$13=""),"",($D$13-B19)/100.0*1000) | D19: =IF(C19="","",SQRT(C19))
C20: =IF(OR(A20="",B20="",$D$13=""),"",($D$13-B20)/100.0*1000) | D20: =IF(C20="","",SQRT(C20))
C21: =IF(OR(A21="",B21="",$D$13=""),"",($D$13-B21)/100.0*1000) | D21: =IF(C21="","",SQRT(C21))
C22: =IF(OR(A22="",B22="",$D$13=""),"",($D$13-B22)/100.0*1000) | D22: =IF(C22="","",SQRT(C22))
C23: =IF(OR(A23="",B23="",$D$13=""),"",($D$13-B23)/100.0*1000) | D23: =IF(C23="","",SQRT(C23))
C24: =IF(OR(A24="",B24="",$D$13=""),"",($D$13-B24)/100.0*1000) | D24: =IF(C24="","",SQRT(C24))
A25: 做法：先看粗掃表在哪一格之間跳起來，回到那一段用 0.1～0.2 V 一階重掃十點；√I_D 欄若呈一條直線就代表那幾點在平方律上，可以拿來外插。
A27: 臨界電壓 V_th（平方根外插）
B28: 量測點 1 | C28: 量測點 2 | D28: 外插結果
A29: V_GS (V) | D29: =IF(OR(B29="",B30="",C29="",C30=""),"",B29-(C29-B29)/(SQRT(C30)-SQRT(B30))*SQRT(B30)) | E29: ← V_th (V)
A30: I_D (mA) | D30: 2.14 | E30: ← LTspice（BS170）的 V_to
D31: =IF(D29="","",IF(OR(D29<0,D29>MIN(B29,C29)),"兩點取在平台上了，重挑","合理")) | E31: ← 合理性檢查
A32: 兩個點都要取自上面的加密掃描、且落在抬頭段（建議 I_D 在 1～5 mA 之間）。取到被 R1 限流的平台（I_D 接近 V_DS/100 Ω）會算出負的 V_th。
A33: 三組的平台高度約等於 V_DS / 100 Ω，那是 R1 在限流、不是元件飽和；要讀的資訊全在抬頭那一段。

Sheet 交報告用
A1: 交報告用表格（版面照 App_Lab3.pdf 第 7 頁與第 9 頁）
A2: 數字由前兩張表帶過來；空白代表當天沒量。直接整塊複製貼進報告
A4: 1. Circuit schematic (characteristic curve, I_D-V_DS)
A5: V_GS = 0 V | D5: V_GS = 2 V
A6: V_DS (experimental setting) | B6: I_D (measure) | D6: V_DS (experimental setting) | E6: I_D (measure)
A7: 1 V | B7: =IF('實驗一 特性曲線'!C6="","",TEXT('實驗一 特性曲線'!C6,"0.000")&" mA") | D7: 1 V | E7: =IF('實驗一 特性曲線'!F6="","",TEXT('實驗一 特性曲線'!F6,"0.000")&" mA")
A8: 2 V | B8: =IF('實驗一 特性曲線'!C7="","",TEXT('實驗一 特性曲線'!C7,"0.000")&" mA") | D8: 2 V | E8: =IF('實驗一 特性曲線'!F7="","",TEXT('實驗一 特性曲線'!F7,"0.000")&" mA")
A9: 3 V | B9: =IF('實驗一 特性曲線'!C8="","",TEXT('實驗一 特性曲線'!C8,"0.000")&" mA") | D9: 3 V | E9: =IF('實驗一 特性曲線'!F8="","",TEXT('實驗一 特性曲線'!F8,"0.000")&" mA")
A10: 4 V | B10: =IF('實驗一 特性曲線'!C9="","",TEXT('實驗一 特性曲線'!C9,"0.000")&" mA") | D10: 4 V | E10: =IF('實驗一 特性曲線'!F9="","",TEXT('實驗一 特性曲線'!F9,"0.000")&" mA")
A11: 5 V | B11: =IF('實驗一 特性曲線'!C10="","",TEXT('實驗一 特性曲線'!C10,"0.000")&" mA") | D11: 5 V | E11: =IF('實驗一 特性曲線'!F10="","",TEXT('實驗一 特性曲線'!F10,"0.000")&" mA")
A13: V_GS = 4 V | D13: V_GS = 6 V
A14: V_DS (experimental setting) | B14: I_D (measure) | D14: V_DS (experimental setting) | E14: I_D (measure)
A15: 1 V | B15: =IF('實驗一 特性曲線'!I6="","",TEXT('實驗一 特性曲線'!I6,"0.000")&" mA") | D15: 1 V | E15: =IF('實驗一 特性曲線'!L6="","",TEXT('實驗一 特性曲線'!L6,"0.000")&" mA")
A16: 2 V | B16: =IF('實驗一 特性曲線'!I7="","",TEXT('實驗一 特性曲線'!I7,"0.000")&" mA") | D16: 2 V | E16: =IF('實驗一 特性曲線'!L7="","",TEXT('實驗一 特性曲線'!L7,"0.000")&" mA")
A17: 3 V | B17: =IF('實驗一 特性曲線'!I8="","",TEXT('實驗一 特性曲線'!I8,"0.000")&" mA") | D17: 3 V | E17: =IF('實驗一 特性曲線'!L8="","",TEXT('實驗一 特性曲線'!L8,"0.000")&" mA")
A18: 4 V | B18: =IF('實驗一 特性曲線'!I9="","",TEXT('實驗一 特性曲線'!I9,"0.000")&" mA") | D18: 4 V | E18: =IF('實驗一 特性曲線'!L9="","",TEXT('實驗一 特性曲線'!L9,"0.000")&" mA")
A19: 5 V | B19: =IF('實驗一 特性曲線'!I10="","",TEXT('實驗一 特性曲線'!I10,"0.000")&" mA") | D19: 5 V | E19: =IF('實驗一 特性曲線'!L10="","",TEXT('實驗一 特性曲線'!L10,"0.000")&" mA")
A22: 2. Circuit schematic (transfer curve, I_D-V_GS)
A23: V_DS = 1 V
A24: V_GS (experimental setting) | B24: I_D (measure)
A25: 0.5 V | B25: =IF('實驗二 轉移曲線'!C6="","",TEXT('實驗二 轉移曲線'!C6,"0.000")&" mA")
A26: 1 V | B26: =IF('實驗二 轉移曲線'!C7="","",TEXT('實驗二 轉移曲線'!C7,"0.000")&" mA")
A27: 2 V | B27: =IF('實驗二 轉移曲線'!C8="","",TEXT('實驗二 轉移曲線'!C8,"0.000")&" mA")
A28: 3 V | B28: =IF('實驗二 轉移曲線'!C9="","",TEXT('實驗二 轉移曲線'!C9,"0.000")&" mA")
A29: 4 V | B29: =IF('實驗二 轉移曲線'!C10="","",TEXT('實驗二 轉移曲線'!C10,"0.000")&" mA")
A30: 5 V | B30: =IF('實驗二 轉移曲線'!C11="","",TEXT('實驗二 轉移曲線'!C11,"0.000")&" mA")
A32: V_DS = 3 V
A33: V_GS (experimental setting) | B33: I_D (measure)
A34: 0.5 V | B34: =IF('實驗二 轉移曲線'!F6="","",TEXT('實驗二 轉移曲線'!F6,"0.000")&" mA")
A35: 1 V | B35: =IF('實驗二 轉移曲線'!F7="","",TEXT('實驗二 轉移曲線'!F7,"0.000")&" mA")
A36: 2 V | B36: =IF('實驗二 轉移曲線'!F8="","",TEXT('實驗二 轉移曲線'!F8,"0.000")&" mA")
A37: 3 V | B37: =IF('實驗二 轉移曲線'!F9="","",TEXT('實驗二 轉移曲線'!F9,"0.000")&" mA")
A38: 4 V | B38: =IF('實驗二 轉移曲線'!F10="","",TEXT('實驗二 轉移曲線'!F10,"0.000")&" mA")
A39: 5 V | B39: =IF('實驗二 轉移曲線'!F11="","",TEXT('實驗二 轉移曲線'!F11,"0.000")&" mA")
A41: V_DS = 5 V
A42: V_GS (experimental setting) | B42: I_D (measure)
A43: 0.5 V | B43: =IF('實驗二 轉移曲線'!I6="","",TEXT('實驗二 轉移曲線'!I6,"0.000")&" mA")
A44: 1 V | B44: =IF('實驗二 轉移曲線'!I7="","",TEXT('實驗二 轉移曲線'!I7,"0.000")&" mA")
A45: 2 V | B45: =IF('實驗二 轉移曲線'!I8="","",TEXT('實驗二 轉移曲線'!I8,"0.000")&" mA")
A46: 3 V | B46: =IF('實驗二 轉移曲線'!I9="","",TEXT('實驗二 轉移曲線'!I9,"0.000")&" mA")
...
